2018-02-09 17:57:08,188 - root - until_log.py[line:51] - ERROR >>> 打开浏览器错误
Traceback (most recent call last):
  File "E:\workspace\YimiAuto\venv\lib\site-packages\selenium\webdriver\common\service.py", line 76, in start
    stdin=PIPE)
  File "C:\Users\suMs\AppData\Local\Programs\Python\Python36-32\lib\subprocess.py", line 709, in __init__
    restore_signals, start_new_session)
  File "C:\Users\suMs\AppData\Local\Programs\Python\Python36-32\lib\subprocess.py", line 997, in _execute_child
    startupinfo)
FileNotFoundError: [WinError 2] 系统找不到指定的文件。

During handling of the above exception, another exception occurred:

Traceback (most recent call last):
  File "E:\workspace\YimiAuto\YimiAutoCurrency\untils\ary.py", line 28, in __init__
    driver = webdriver.Chrome()
  File "E:\workspace\YimiAuto\venv\lib\site-packages\selenium\webdriver\chrome\webdriver.py", line 68, in __init__
    self.service.start()
  File "E:\workspace\YimiAuto\venv\lib\site-packages\selenium\webdriver\common\service.py", line 83, in start
    os.path.basename(self.path), self.start_error_message)
selenium.common.exceptions.WebDriverException: Message: 'chromedriver' executable needs to be in PATH. Please see https://sites.google.com/a/chromium.org/chromedriver/home

